# [Combine] Operator: Handling Errors

###### tags: `Combine`

### 목차

- Mapping
- Filtering
- Reducing
- Mathematical Operations
- Applying Matching Criteria
- Applying Sequence Operations
- Selecting Specific Elements
- CombineLatest
- Merge
- Zip
- FlatMap
- **Handling Errors**
- Controlling Timing
- Encoding and Decoding
- Identifying Properties with Key Paths
- Working with Multiple Subscribers
- Buffering Elements
- Performing Type-Erasure
- Specifying Schedulers
- Adding Explicit Connectability
- Connecting Simple Subscribers
- Debugging

flatMap은 왜 안하냐구요?
하다가 어려워서 도망쳤습니다 ㅠㅠ 맨 마지막에 할래요..

### assertNoFailure(_:file:line:)

> Raises a fatal error when its upstream publisher fails, and otherwise republishes all received input.

UIKit에 옵셔널 강제추출이있다면, combine에는 assertNoFailure가 있습니다.
error가 안난다고 가정하는거고, error나면 바로 fatalError가 뜹니다.

네.. 못쓰겠죠? 그냥 혼자 공부할때나 쓸 수 있겠네요 ㅠㅠ

```swift
let subject = CurrentValueSubject<Int, MyError>(1)

subject
    .assertNoFailure()
    .sink(
        receiveCompletion: {print($0)},
        receiveValue: {print($0)}
    )

subject.send(2)
subject.send(completion: .failure(.all))    // 바로 앱이 죽어요
```

### catch(_:)

> Handles errors from an upstream publisher by replacing it with another publisher.

do catch 느낌인듯?

```swift
enum MyError: Error { case all }

let subject = CurrentValueSubject<Int, MyError>(1)

subject
    .catch{ _ in Just(0) }
    .sink(
        receiveCompletion: {print($0)},
        receiveValue: {print($0)}
    )

subject.send(2)
subject.send(completion: .failure(.all))

/*
1
2
0
finished
*/
```

오.. 분명 error를 명시적으로 보내도 죽지않고 살아나네요. 대박

### tryCatch(_:)

> Handles errors from an upstream publisher by either replacing it with another publisher or throwing a new error.

catch는 error가 발생했을때 다른 publsiher로 대체해주잖아요?
tryCatch는 두가지의 옵션을 제공합니다

- 새로운 에러를 던지기
- 다른 publisher도 대체하기

그니깐 그냥 catch의 확장버전인거죠?
여기서는 새로운 에러를 던져볼깨요!

```swift
enum MyError: Error { case all }

let subject = CurrentValueSubject<Int, MyError>(1)

subject
    .tryCatch{ error -> AnyPublisher<Int,Error> in
        throw MyError.all
    }
    .sink(
        receiveCompletion: {print($0)},
        receiveValue: {print($0)}
    )

subject.send(2)
subject.send(completion: .failure(.all))
/*
1
2
failure(__lldb_expr_553.MyError.all)
*/
```

### retry(_:)

> Attempts to recreate a failed subscription with the upstream publisher up to the number of times you specify.

retry는 주로 URL통신에서 많이 쓰이는데, 아무래도 네트워크작업은 실패할 수가 있잖아요?
그때 k회만큼 재시도 하는 연산자입니다. 좋네요..!!

```swift
var bag = Set<AnyCancellable>()

struct WebSiteData: Codable {
    var rawHTML: String
}

let myURL = URL(string: "https://www.example.com")

URLSession.shared.dataTaskPublisher(for: myURL!)
    .retry(3)
    .map{ (page) -> WebSiteData in
        return WebSiteData(rawHTML: String(decoding: page.data, as: UTF8.self))
    }
    .catch { error in
        return Just(WebSiteData(rawHTML: "<HTML>Unable to load page - timed out.</HTML>"))
    }
    .sink(
        receiveCompletion: { print ("completion: \($0)") },
        receiveValue: { print ("value: \($0)") }
    )
    .store(in: &bag)
```

뭐.. 더 말할거 없죠?
이게 error 핸들링 방법인가봐요.. 생각보다 별게 없네요
